Workbook

Sheet Read me
B1: Portfolio workbook · Full (Example)
B2: A record of every program and project in one portfolio, kept by hand. Six tabs: Read me, Portfolio, Register, Funding, Steering and Checks.
A3: Example. Wexbridge Quill Software and everyone in it are made up. Clear the white cells to start your own.
A5: Filling it in
A6: 1 | B6: On Portfolio, type the portfolio's name, director, manager and status. If a steering group meets, pick how often, and add a First review date if it hasn't met yet.
A7: 2 | B7: On Register, add a row for every program and every project, with Sits under, Status and Owner. On projects, pick an Approach in the last column, after Check.
A8: 3 | B8: Type Planned finish, Latest forecast and Forecast spend, and Budget on programs and on projects directly under Portfolio. On Funding, type the envelope, its currency and where it came from.
A9: 4 | B9: Read Health and Check on Register, and the Checks tab for every result. Write a Variance note on every Amber or Red row, ending with your name.
A10: 5 | B10: After each steering meeting, add it under Meetings on Steering. Then log its decisions, each with one accountable person and who recorded it, and any actions with an owner and a due date.
A12: YOUR LOGO
B13: The FRQZ logo is in cell A1 on every tab. To use your own, delete it and insert your logo in A1, on each tab.
A15: NAMES
B16: Type each person's name the same way every time, with a role in brackets if you like: Priya (CTO). Names are matched exactly as typed, so Priya and Priya (CTO) count as two people.
A18: READING THE MARKS
A19: ■ Red | B19: Late, or over budget, by more than your limit. The limits are on the Checks tab, and you can change them.
A20: ◧ Amber | B20: Late, or over budget, within your limit.
A21: □ On track | B21: A date or a budget was read, and nothing is late or over.
A22: Not read | B22: Nothing to judge from yet. A project with a Planned finish and no Latest forecast reads Not read; if the date hasn't moved, type it again as the forecast. A Sprint project always reads Not read.
A23: Not counted | B23: Proposed, Completed or Terminated. Left out of every count.
A24: △ | B24: A check found something, and the words say what. Filter the Check column on △ to list them all.
A25: ○ Clear | B25: The check found nothing.
A27: HOW HEALTH IS WORKED OUT
B28: Dates: a project is Red once its Planned finish has passed while it's still Active or Paused. Otherwise a Latest forecast past the plan by more than your limit is Red, and a smaller slip is Amber.
B29: Money: spend over Budget by more than your limit is Red, and a smaller overrun is Amber. A program's spend is its projects' Forecast spend added up.
B30: Health is the worse of the two. A program with no Latest forecast uses the latest among its projects. Its colour never hides theirs: Projects inside counts its Red and Amber projects beside it.
A32: GREY COLUMNS
B33: Grey cells are worked out from what you type. Don't type over them: a typed value replaces the formula.
B34: Owner's current rows counts the Active and Paused rows that carry each owner's name, so you can see who's spread thin. It sets no limit.
A36: THE STARTER WORKBOOK
B37: A small team that wants fewer tabs can use the Starter workbook. Its Register columns A to L match this one, so rows paste across.
A39: ABOUT THIS EXAMPLE
B40: Wexbridge Quill Software is made up, and so is everyone in it.
B41: Four checks fail on purpose. Billing and Payments Program has no sponsor. Support Tooling Replacement sits under a program that isn't on the sheet, and Internal Wiki Cleanup is paused, so still current, outside the portfolio. The budgets add up to 30,000 USD more than the envelope. And the 15 Oct 2026 decision was recorded by the manager, where decisions are the director's to record.
B42: Support Tooling Replacement is a Sprint project, so its Health reads Not read. The other eight checks are clear. The dates are in 2026 and 2027, so the marks will change as time passes.

Sheet Portfolio
B1: Portfolio (Example)
A2: One portfolio per workbook. Type in the white cells; the grey ones are worked out.
A3: Example. Wexbridge Quill Software and everyone in it are made up. Clear the white cells to start your own.
A5: THE PORTFOLIO
A6: PORTFOLIO NAME | B6: Product and Platform | C6: What you call the work this workbook covers. Required.
A7: DIRECTOR | B7: Priya (CTO) | C7: The person accountable for the portfolio's direction and benefits. A name, with a role in brackets if you like. Required.
A8: MANAGER | B8: Tomasz (PMO Head) | C8: The person who runs it day to day and keeps the register. Can be the director. Required.
A9: STATUS | B9: Active | C9: Where the portfolio is in its life. Blank counts as Active. Reviews are checked only while it's Active.
A10: REVIEW CADENCE | B10: Quarterly | C10: How often the steering group reviews the portfolio. Leave blank if there isn't one.
A11: FIRST REVIEW | B11: 46037 | C11: The date of the first review, while no meeting is logged on Steering. Optional.
A12: LAST REVIEW | B12: =IF(COUNT(Steering!$G$6:$G$55)=0,"",MAX(Steering!$G$6:$G$55)) | C12: Worked out: the latest meeting date on Steering.
A13: NEXT REVIEW | B13: =IF($B$10="","No review date",IF($B$12<>"",IF($B$10="Monthly",EDATE($B$12,1),IF($B$10="Quarterly",EDATE($B$12,3),IF($B$10="Twice a year",EDATE($B$12,6),EDATE($B$12,12)))),IF($B$11<>"",$B$11,"No review date"))) | C13: Worked out: Last review plus the cadence, or First review until a meeting is logged.
A14: PEOPLE CHECK | B14: =IF(AND($B$7<>"",$B$8<>""),"○ Clear","△ "&IF(AND($B$7="",$B$8=""),"Director and manager not named",IF($B$7="","Director not named","Manager not named"))) | C14: Shows △ when the director or the manager isn't named.
A15: REVIEW CHECK | B15: =IF(OR($B$10="",AND($B$9<>"",$B$9<>"Active")),"○ Clear",IF($B$13="No review date","△ No review date",IF($B$13<TODAY(),"△ Review overdue since "&TEXT($B$13,"d mmm yyyy"),"○ Clear"))) | C15: Shows △ when the next review has passed, or a cadence is set with no review date.
A17: COUNTS BY HEALTH | C17: Programs and projects directly under Portfolio, one count each. A program's own projects are counted beside it on Register.
A18: ■ Red | B18: =COUNTIFS(Register!$C$6:$C$305,"Portfolio",Register!$M$6:$M$305,"■ Red")
A19: ◧ Amber | B19: =COUNTIFS(Register!$C$6:$C$305,"Portfolio",Register!$M$6:$M$305,"◧ Amber")
A20: □ On track | B20: =COUNTIFS(Register!$C$6:$C$305,"Portfolio",Register!$M$6:$M$305,"□ On track")
A21: Not read | B21: =COUNTIFS(Register!$C$6:$C$305,"Portfolio",Register!$M$6:$M$305,"Not read")
A22: CURRENT ROWS OUTSIDE THE PORTFOLIO | B22: =COUNTIFS(Register!$C$6:$C$305,"Outside the portfolio",Register!$Q$6:$Q$305,1) | C22: Active or Paused rows with Sits under set to Outside the portfolio. Left out of the counts above.
A24: CHECKS | B24: =Checks!$B$10 | C24: Every result is on the Checks tab.
A26: OBJECTIVES
A27: Objective | B27: Owner | C27: Measure and target | D27: Target date | E27: Linked rows
A28: Cut the time to bring on a new customer | B28: Priya (CTO) | C28: Days from signed order to first live use: 21 | D28: 46568 | E28: =IF($A28="","",COUNTIF(Register!$G$6:$G$305,$A28))
A29: Pass the annual audit with no major findings | B29: Imani (Security Lead) | C29: Major findings at audit: 0 | D29: 46444 | E29: =IF($A29="","",COUNTIF(Register!$G$6:$G$305,$A29))
A30: Move all billing to the new engine before renewals | B30: Hugo (Program Manager) | C30: Share of invoices from the new engine: 100% | D30: 46660 | E30: =IF($A30="","",COUNTIF(Register!$G$6:$G$305,$A30))
E31: =IF($A31="","",COUNTIF(Register!$G$6:$G$305,$A31))
E32: =IF($A32="","",COUNTIF(Register!$G$6:$G$305,$A32))
E33: =IF($A33="","",COUNTIF(Register!$G$6:$G$305,$A33))
E34: =IF($A34="","",COUNTIF(Register!$G$6:$G$305,$A34))
E35: =IF($A35="","",COUNTIF(Register!$G$6:$G$305,$A35))
E36: =IF($A36="","",COUNTIF(Register!$G$6:$G$305,$A36))
E37: =IF($A37="","",COUNTIF(Register!$G$6:$G$305,$A37))

Sheet Register
B1: Register (Example)
A2: =IF(Portfolio!$B$6="","","Portfolio: "&Portfolio!$B$6)
A3: Example. Wexbridge Quill Software and everyone in it are made up. Clear the white cells to start your own.
A5: Name | B5: Level | C5: Sits under | D5: Status | E5: Owner | F5: Sponsor | G5: Objective | H5: Planned finish | I5: Latest forecast | J5: Forecast spend | K5: Budget | L5: Variance note | M5: Health | N5: Projects inside | O5: Owner's current rows | P5: Check | Q5: Helper, worked out | R5: Helper, worked out | S5: Helper, worked out | T5: Helper, worked out | U5: Helper, worked out | V5: Helper, worked out | W5: Helper, worked out | X5: Helper, worked out | Y5: Helper, worked out | Z5: Helper, worked out | AA5: Helper, worked out | AB5: Helper, worked out | AC5: Helper, worked out | AD5: Helper, worked out | AE5: Helper, worked out | AF5: Approach | AG5: Helper, worked out | AH5: Helper, worked out | AI5: Helper, worked out
A6: Customer Platform Modernisation | B6: Program | C6: Portfolio | D6: Active | E6: Dara (Program Manager) | F6: Priya (CTO) | G6: Cut the time to bring on a new customer | H6: 46507 | K6: 1100000 | M6: =IF($A6="","",IF($D6="","Not read",IF($Q6=0,"Not counted",IF(MAX($X6,$Y6)=3,"■ Red",IF(MAX($X6,$Y6)=2,"◧ Amber",IF(MAX($X6,$Y6)=1,"□ On track","Not read")))))) | N6: =IF(OR($A6="",$B6<>"Program"),"","■ "&COUNTIFS($C$6:$C$305,$A6,$M$6:$M$305,"■ Red")&" Red, ◧ "&COUNTIFS($C$6:$C$305,$A6,$M$6:$M$305,"◧ Amber")&" Amber") | O6: =IF(OR($A6="",$E6=""),"",COUNTIFS($E$6:$E$305,$E6,$D$6:$D$305,"Active")+COUNTIFS($E$6:$E$305,$E6,$D$6:$D$305,"Paused")) | P6: =IF($A6="","",IF($AE6=0,"○ Clear",IF($AA6=1,"△ No owner",IF($AC6=1,"△ Check Sits under",IF($AC6=2,"△ Outside the portfolio",IF($AB6=1,"△ No sponsor",IF($AH6=1,"△ Name used twice",IF($AG6=1,"△ Budget only counts under Portfolio","△ No variance note"))))))&IF($AE6>1," (+"&($AE6-1)&" more)",""))) | Q6: =IF(AND($A6<>"",OR($D6="Active",$D6="Paused")),1,0) | R6: Portfolio | S6: =IF(AND($A6<>"",$B6="Program"),COUNTIFS($B$6:$B6,"Program",$A$6:$A6,"<>"),"") | T6: =IF(AND($A6<>"",$B6="Program"),SUMPRODUCT(MAX(($C$6:$C$305=$A6)*($B$6:$B$305="Project")*($D$6:$D$305<>"Proposed")*$I$6:$I$305)),0) | U6: =IF($I6<>"",$I6,IF($T6>0,$T6,"")) | V6: =IF(AND($A6<>"",$B6="Program"),SUMIFS($J$6:$J$305,$C$6:$C$305,$A6,$B$6:$B$305,"Project",$D$6:$D$305,"<>Proposed"),0) | W6: =IF(AND($A6<>"",$B6="Program"),COUNTIFS($C$6:$C$305,$A6,$B$6:$B$305,"Project",$D$6:$D$305,"<>Proposed")-COUNTIFS($C$6:$C$305,$A6,$B$6:$B$305,"Project",$D$6:$D$305,"<>Proposed",$J$6:$J$305,">=0"),0) | X6: =IF(OR($Q6=0,$H6="",$AF6="Sprint"),0,IF(AND($B6="Project",$H6<TODAY()),3,IF($U6="",0,IF($U6<=$H6,1,IF(NETWORKDAYS($H6,$U6)-1>IF($B6="Program",Checks!$B$7,Checks!$B$6),3,2))))) | Y6: =IF(OR($Q6=0,$K6="",$K6=0,$AF6="Sprint"),0,IF(AND($B6="Project",$J6=""),0,IF(IF($B6="Program",$V6,$J6)>$K6*(1+Checks!$B$8),3,IF(IF($B6="Program",$V6,$J6)>$K6,2,IF(AND($B6="Program",OR($W6>0,$V6=0)),0,1))))) | Z6: =IF($A6="",0,IF($C6="Portfolio",1,IF(AND($B6="Project",$C6<>"",$C6<>"Outside the portfolio"),IFERROR(IF(AND(INDEX($B$6:$B$305,MATCH($C6,$A$6:$A$305,0))="Program",INDEX($C$6:$C$305,MATCH($C6,$A$6:$A$305,0))="Portfolio"),1,0),0),0))) | AA6: =IF(AND($A6<>"",$E6="",OR($Q6=1,$D6="Proposed")),1,0) | AB6: =IF(AND($A6<>"",$B6="Program",$F6="",$Q6=1),1,0) | AC6: =IF(OR($A6="",$D6="Completed",$D6="Terminated"),0,IF($C6="",1,IF($C6="Portfolio",0,IF($C6="Outside the portfolio",IF($Q6=1,2,0),IF($B6="Project",IF(IFERROR(INDEX($B$6:$B$305,MATCH($C6,$A$6:$A$305,0)),"")="Program",0,1),1))))) | AD6: =IF(AND($A6<>"",OR($M6="■ Red",$M6="◧ Amber"),$L6=""),1,0) | AE6: =$AA6+$AB6+IF($AC6>0,1,0)+$AD6+$AG6+$AH6 | AG6: =IF(AND($A6<>"",$K6<>"",$C6<>"Portfolio",$D6<>"Completed",$D6<>"Terminated"),1,0) | AH6: =IF(AND($A6<>"",COUNTIF($A$6:$A$305,$A6)>1),1,0) | AI6: =IF(AND($A6<>"",$C6="Portfolio"),COUNTIFS($C$6:$C6,"Portfolio",$A$6:$A6,"<>"),"")
A7: Data Migration Wave 2 | B7: Project | C7: Customer Platform Modernisation | D7: Active | E7: Kofi (Delivery Lead) | G7: Cut the time to bring on a new customer | H7: 46444 | I7: 46458 | J7: 520000 | L7: Schema fix agreed with the vendor; the new date holds only if it lands by 5 Nov. Kofi | M7: =IF($A7="","",IF($D7="","Not read",IF($Q7=0,"Not counted",IF(MAX($X7,$Y7)=3,"■ Red",IF(MAX($X7,$Y7)=2,"◧ Amber",IF(MAX($X7,$Y7)=1,"□ On track","Not read")))))) | N7: =IF(OR($A7="",$B7<>"Program"),"","■ "&COUNTIFS($C$6:$C$305,$A7,$M$6:$M$305,"■ Red")&" Red, ◧ "&COUNTIFS($C$6:$C$305,$A7,$M$6:$M$305,"◧ Amber")&" Amber") | O7: =IF(OR($A7="",$E7=""),"",COUNTIFS($E$6:$E$305,$E7,$D$6:$D$305,"Active")+COUNTIFS($E$6:$E$305,$E7,$D$6:$D$305,"Paused")) | P7: =IF($A7="","",IF($AE7=0,"○ Clear",IF($AA7=1,"△ No owner",IF($AC7=1,"△ Check Sits under",IF($AC7=2,"△ Outside the portfolio",IF($AB7=1,"△ No sponsor",IF($AH7=1,"△ Name used twice",IF($AG7=1,"△ Budget only counts under Portfolio","△ No variance note"))))))&IF($AE7>1," (+"&($AE7-1)&" more)",""))) | Q7: =IF(AND($A7<>"",OR($D7="Active",$D7="Paused")),1,0) | R7: Outside the portfolio | S7: =IF(AND($A7<>"",$B7="Program"),COUNTIFS($B$6:$B7,"Program",$A$6:$A7,"<>"),"") | T7: =IF(AND($A7<>"",$B7="Program"),SUMPRODUCT(MAX(($C$6:$C$305=$A7)*($B$6:$B$305="Project")*($D$6:$D$305<>"Proposed")*$I$6:$I$305)),0) | U7: =IF($I7<>"",$I7,IF($T7>0,$T7,"")) | V7: =IF(AND($A7<>"",$B7="Program"),SUMIFS($J$6:$J$305,$C$6:$C$305,$A7,$B$6:$B$305,"Project",$D$6:$D$305,"<>Proposed"),0) | W7: =IF(AND($A7<>"",$B7="Program"),COUNTIFS($C$6:$C$305,$A7,$B$6:$B$305,"Project",$D$6:$D$305,"<>Proposed")-COUNTIFS($C$6:$C$305,$A7,$B$6:$B$305,"Project",$D$6:$D$305,"<>Proposed",$J$6:$J$305,">=0"),0) | X7: =IF(OR($Q7=0,$H7="",$AF7="Sprint"),0,IF(AND($B7="Project",$H7<TODAY()),3,IF($U7="",0,IF($U7<=$H7,1,IF(NETWORKDAYS($H7,$U7)-1>IF($B7="Program",Checks!$B$7,Checks!$B$6),3,2))))) | Y7: =IF(OR($Q7=0,$K7="",$K7=0,$AF7="Sprint"),0,IF(AND($B7="Project",$J7=""),0,IF(IF($B7="Program",$V7,$J7)>$K7*(1+Checks!$B$8),3,IF(IF($B7="Program",$V7,$J7)>$K7,2,IF(AND($B7="Program",OR($W7>0,$V7=0)),0,1))))) | Z7: =IF($A7="",0,IF($C7="Portfolio",1,IF(AND($B7="Project",$C7<>"",$C7<>"Outside the portfolio"),IFERROR(IF(AND(INDEX($B$6:$B$305,MATCH($C7,$A$6:$A$305,0))="Program",INDEX($C$6:$C$305,MATCH($C7,$A$6:$A$305,0))="Portfolio"),1,0),0),0))) | AA7: =IF(AND($A7<>"",$E7="",OR($Q7=1,$D7="Proposed")),1,0) | AB7: =IF(AND($A7<>"",$B7="Program",$F7="",$Q7=1),1,0) | AC7: =IF(OR($A7="",$D7="Completed",$D7="Terminated"),0,IF($C7="",1,IF($C7="Portfolio",0,IF($C7="Outside the portfolio",IF($Q7=1,2,0),IF($B7="Project",IF(IFERROR(INDEX($B$6:$B$305,MATCH($C7,$A$6:$A$305,0)),"")="Program",0,1),1))))) | AD7: =IF(AND($A7<>"",OR($M7="■ Red",$M7="◧ Amber"),$L7=""),1,0) | AE7: =$AA7+$AB7+IF($AC7>0,1,0)+$AD7+$AG7+$AH7 | AF7: Waterfall | AG7: =IF(AND($A7<>"",$K7<>"",$C7<>"Portfolio",$D7<>"Completed",$D7<>"Terminated"),1,0) | AH7: =IF(AND($A7<>"",COUNTIF($A$6:$A$305,$A7)>1),1,0) | AI7: =IF(AND($A7<>"",$C7="Portfolio"),COUNTIFS($C$6:$C7,"Portfolio",$A$6:$A7,"<>"),"")
A8: Billing and Payments Program | B8: Program | C8: Portfolio | D8: Active | E8: Hugo (Program Manager) | G8: Move all billing to the new engine before renewals | H8: 46568 | K8: 900000 | M8: =IF($A8="","",IF($D8="","Not read",IF($Q8=0,"Not counted",IF(MAX($X8,$Y8)=3,"■ Red",IF(MAX($X8,$Y8)=2,"◧ Amber",IF(MAX($X8,$Y8)=1,"□ On track","Not read")))))) | N8: =IF(OR($A8="",$B8<>"Program"),"","■ "&COUNTIFS($C$6:$C$305,$A8,$M$6:$M$305,"■ Red")&" Red, ◧ "&COUNTIFS($C$6:$C$305,$A8,$M$6:$M$305,"◧ Amber")&" Amber") | O8: =IF(OR($A8="",$E8=""),"",COUNTIFS($E$6:$E$305,$E8,$D$6:$D$305,"Active")+COUNTIFS($E$6:$E$305,$E8,$D$6:$D$305,"Paused")) | P8: =IF($A8="","",IF($AE8=0,"○ Clear",IF($AA8=1,"△ No owner",IF($AC8=1,"△ Check Sits under",IF($AC8=2,"△ Outside the portfolio",IF($AB8=1,"△ No sponsor",IF($AH8=1,"△ Name used twice",IF($AG8=1,"△ Budget only counts under Portfolio","△ No variance note"))))))&IF($AE8>1," (+"&($AE8-1)&" more)",""))) | Q8: =IF(AND($A8<>"",OR($D8="Active",$D8="Paused")),1,0) | R8: =IFERROR(INDEX($A$6:$A$305,MATCH(1,$S$6:$S$305,0)),"") | S8: =IF(AND($A8<>"",$B8="Program"),COUNTIFS($B$6:$B8,"Program",$A$6:$A8,"<>"),"") | T8: =IF(AND($A8<>"",$B8="Program"),SUMPRODUCT(MAX(($C$6:$C$305=$A8)*($B$6:$B$305="Project")*($D$6:$D$305<>"Proposed")*$I$6:$I$305)),0) | U8: =IF($I8<>"",$I8,IF($T8>0,$T8,"")) | V8: =IF(AND($A8<>"",$B8="Program"),SUMIFS($J$6:$J$305,$C$6:$C$305,$A8,$B$6:$B$305,"Project",$D$6:$D$305,"<>Proposed"),0) | W8: =IF(AND($A8<>"",$B8="Program"),COUNTIFS($C$6:$C$305,$A8,$B$6:$B$305,"Project",$D$6:$D$305,"<>Proposed")-COUNTIFS($C$6:$C$305,$A8,$B$6:$B$305,"Project",$D$6:$D$305,"<>Proposed",$J$6:$J$305,">=0"),0) | X8: =IF(OR($Q8=0,$H8="",$AF8="Sprint"),0,IF(AND($B8="Project",$H8<TODAY()),3,IF($U8="",0,IF($U8<=$H8,1,IF(NETWORKDAYS($H8,$U8)-1>IF($B8="Program",Checks!$B$7,Checks!$B$6),3,2))))) | Y8: =IF(OR($Q8=0,$K8="",$K8=0,$AF8="Sprint"),0,IF(AND($B8="Project",$J8=""),0,IF(IF($B8="Program",$V8,$J8)>$K8*(1+Checks!$B$8),3,IF(IF($B8="Program",$V8,$J8)>$K8,2,IF(AND($B8="Program",OR($W8>0,$V8=0)),0,1))))) | Z8: =IF($A8="",0,IF($C8="Portfolio",1,IF(AND($B8="Project",$C8<>"",$C8<>"Outside the portfolio"),IFERROR(IF(AND(INDEX($B$6:$B$305,MATCH($C8,$A$6:$A$305,0))="Program",INDEX($C$6:$C$305,MATCH($C8,$A$6:$A$305,0))="Portfolio"),1,0),0),0))) | AA8: =IF(AND($A8<>"",$E8="",OR($Q8=1,$D8="Proposed")),1,0) | AB8: =IF(AND($A8<>"",$B8="Program",$F8="",$Q8=1),1,0) | AC8: =IF(OR($A8="",$D8="Completed",$D8="Terminated"),0,IF($C8="",1,IF($C8="Portfolio",0,IF($C8="Outside the portfolio",IF($Q8=1,2,0),IF($B8="Project",IF(IFERROR(INDEX($B$6:$B$305,MATCH($C8,$A$6:$A$305,0)),"")="Program",0,1),1))))) | AD8: =IF(AND($A8<>"",OR($M8="■ Red",$M8="◧ Amber"),$L8=""),1,0) | AE8: =$AA8+$AB8+IF($AC8>0,1,0)+$AD8+$AG8+$AH8 | AG8: =IF(AND($A8<>"",$K8<>"",$C8<>"Portfolio",$D8<>"Completed",$D8<>"Terminated"),1,0) | AH8: =IF(AND($A8<>"",COUNTIF($A$6:$A$305,$A8)>1),1,0) | AI8: =IF(AND($A8<>"",$C8="Portfolio"),COUNTIFS($C$6:$C8,"Portfolio",$A$6:$A8,"<>"),"")
A9: Billing Engine Rewrite | B9: Project | C9: Billing and Payments Program | D9: Active | E9: Anders (Engineering Manager) | G9: Move all billing to the new engine before renewals | H9: 46568 | I9: 46568 | J9: 780000 | M9: =IF($A9="","",IF($D9="","Not read",IF($Q9=0,"Not counted",IF(MAX($X9,$Y9)=3,"■ Red",IF(MAX($X9,$Y9)=2,"◧ Amber",IF(MAX($X9,$Y9)=1,"□ On track","Not read")))))) | N9: =IF(OR($A9="",$B9<>"Program"),"","■ "&COUNTIFS($C$6:$C$305,$A9,$M$6:$M$305,"■ Red")&" Red, ◧ "&COUNTIFS($C$6:$C$305,$A9,$M$6:$M$305,"◧ Amber")&" Amber") | O9: =IF(OR($A9="",$E9=""),"",COUNTIFS($E$6:$E$305,$E9,$D$6:$D$305,"Active")+COUNTIFS($E$6:$E$305,$E9,$D$6:$D$305,"Paused")) | P9: =IF($A9="","",IF($AE9=0,"○ Clear",IF($AA9=1,"△ No owner",IF($AC9=1,"△ Check Sits under",IF($AC9=2,"△ Outside the portfolio",IF($AB9=1,"△ No sponsor",IF($AH9=1,"△ Name used twice",IF($AG9=1,"△ Budget only counts under Portfolio","△ No variance note"))))))&IF($AE9>1," (+"&($AE9-1)&" more)",""))) | Q9: =IF(AND($A9<>"",OR($D9="Active",$D9="Paused")),1,0) | R9: =IFERROR(INDEX($A$6:$A$305,MATCH(2,$S$6:$S$305,0)),"") | S9: =IF(AND($A9<>"",$B9="Program"),COUNTIFS($B$6:$B9,"Program",$A$6:$A9,"<>"),"") | T9: =IF(AND($A9<>"",$B9="Program"),SUMPRODUCT(MAX(($C$6:$C$305=$A9)*($B$6:$B$305="Project")*($D$6:$D$305<>"Proposed")*$I$6:$I$305)),0) | U9: =IF($I9<>"",$I9,IF($T9>0,$T9,"")) | V9: =IF(AND($A9<>"",$B9="Program"),SUMIFS($J$6:$J$305,$C$6:$C$305,$A9,$B$6:$B$305,"Project",$D$6:$D$305,"<>Proposed"),0) | W9: =IF(AND($A9<>"",$B9="Program"),COUNTIFS($C$6:$C$305,$A9,$B$6:$B$305,"Project",$D$6:$D$305,"<>Proposed")-COUNTIFS($C$6:$C$305,$A9,$B$6:$B$305,"Project",$D$6:$D$305,"<>Proposed",$J$6:$J$305,">=0"),0) | X9: =IF(OR($Q9=0,$H9="",$AF9="Sprint"),0,IF(AND($B9="Project",$H9<TODAY()),3,IF($U9="",0,IF($U9<=$H9,1,IF(NETWORKDAYS($H9,$U9)-1>IF($B9="Program",Checks!$B$7,Checks!$B$6),3,2))))) | Y9: =IF(OR($Q9=0,$K9="",$K9=0,$AF9="Sprint"),0,IF(AND($B9="Project",$J9=""),0,IF(IF($B9="Program",$V9,$J9)>$K9*(1+Checks!$B$8),3,IF(IF($B9="Program",$V9,$J9)>$K9,2,IF(AND($B9="Program",OR($W9>0,$V9=0)),0,1))))) | Z9: =IF($A9="",0,IF($C9="Portfolio",1,IF(AND($B9="Project",$C9<>"",$C9<>"Outside the portfolio"),IFERROR(IF(AND(INDEX($B$6:$B$305,MATCH($C9,$A$6:$A$305,0))="Program",INDEX($C$6:$C$305,MATCH($C9,$A$6:$A$305,0))="Portfolio"),1,0),0),0))) | AA9: =IF(AND($A9<>"",$E9="",OR($Q9=1,$D9="Proposed")),1,0) | AB9: =IF(AND($A9<>"",$B9="Program",$F9="",$Q9=1),1,0) | AC9: =IF(OR($A9="",$D9="Completed",$D9="Terminated"),0,IF($C9="",1,IF($C9="Portfolio",0,IF($C9="Outside the portfolio",IF($Q9=1,2,0),IF($B9="Project",IF(IFERROR(INDEX($B$6:$B$305,MATCH($C9,$A$6:$A$305,0)),"")="Program",0,1),1))))) | AD9: =IF(AND($A9<>"",OR($M9="■ Red",$M9="◧ Amber"),$L9=""),1,0) | AE9: =$AA9+$AB9+IF($AC9>0,1,0)+$AD9+$AG9+$AH9 | AF9: Waterfall | AG9: =IF(AND($A9<>"",$K9<>"",$C9<>"Portfolio",$D9<>"Completed",$D9<>"Terminated"),1,0) | AH9: =IF(AND($A9<>"",COUNTIF($A$6:$A$305,$A9)>1),1,0) | AI9: =IF(AND($A9<>"",$C9="Portfolio"),COUNTIFS($C$6:$C9,"Portfolio",$A$6:$A9,"<>"),"")
A10: Invoice Tax Rules | B10: Project | C10: Billing and Payments Program | D10: Proposed | E10: Hugo (Program Manager) | M10: =IF($A10="","",IF($D10="","Not read",IF($Q10=0,"Not counted",IF(MAX($X10,$Y10)=3,"■ Red",IF(MAX($X10,$Y10)=2,"◧ Amber",IF(MAX($X10,$Y10)=1,"□ On track","Not read")))))) | N10: =IF(OR($A10="",$B10<>"Program"),"","■ "&COUNTIFS($C$6:$C$305,$A10,$M$6:$M$305,"■ Red")&" Red, ◧ "&COUNTIFS($C$6:$C$305,$A10,$M$6:$M$305,"◧ Amber")&" Amber") | O10: =IF(OR($A10="",$E10=""),"",COUNTIFS($E$6:$E$305,$E10,$D$6:$D$305,"Active")+COUNTIFS($E$6:$E$305,$E10,$D$6:$D$305,"Paused")) | P10: =IF($A10="","",IF($AE10=0,"○ Clear",IF($AA10=1,"△ No owner",IF($AC10=1,"△ Check Sits under",IF($AC10=2,"△ Outside the portfolio",IF($AB10=1,"△ No sponsor",IF($AH10=1,"△ Name used twice",IF($AG10=1,"△ Budget only counts under Portfolio","△ No variance note"))))))&IF($AE10>1," (+"&($AE10-1)&" more)",""))) | Q10: =IF(AND($A10<>"",OR($D10="Active",$D10="Paused")),1,0) | R10: =IFERROR(INDEX($A$6:$A$305,MATCH(3,$S$6:$S$305,0)),"") | S10: =IF(AND($A10<>"",$B10="Program"),COUNTIFS($B$6:$B10,"Program",$A$6:$A10,"<>"),"") | T10: =IF(AND($A10<>"",$B10="Program"),SUMPRODUCT(MAX(($C$6:$C$305=$A10)*($B$6:$B$305="Project")*($D$6:$D$305<>"Proposed")*$I$6:$I$305)),0) | U10: =IF($I10<>"",$I10,IF($T10>0,$T10,"")) | V10: =IF(AND($A10<>"",$B10="Program"),SUMIFS($J$6:$J$305,$C$6:$C$305,$A10,$B$6:$B$305,"Project",$D$6:$D$305,"<>Proposed"),0) | W10: =IF(AND($A10<>"",$B10="Program"),COUNTIFS($C$6:$C$305,$A10,$B$6:$B$305,"Project",$D$6:$D$305,"<>Proposed")-COUNTIFS($C$6:$C$305,$A10,$B$6:$B$305,"Project",$D$6:$D$305,"<>Proposed",$J$6:$J$305,">=0"),0) | X10: =IF(OR($Q10=0,$H10="",$AF10="Sprint"),0,IF(AND($B10="Project",$H10<TODAY()),3,IF($U10="",0,IF($U10<=$H10,1,IF(NETWORKDAYS($H10,$U10)-1>IF($B10="Program",Checks!$B$7,Checks!$B$6),3,2))))) | Y10: =IF(OR($Q10=0,$K10="",$K10=0,$AF10="Sprint"),0,IF(AND($B10="Project",$J10=""),0,IF(IF($B10="Program",$V10,$J10)>$K10*(1+Checks!$B$8),3,IF(IF($B10="Program",$V10,$J10)>$K10,2,IF(AND($B10="Program",OR($W10>0,$V10=0)),0,1))))) | Z10: =IF($A10="",0,IF($C10="Portfolio",1,IF(AND($B10="Project",$C10<>"",$C10<>"Outside the portfolio"),IFERROR(IF(AND(INDEX($B$6:$B$305,MATCH($C10,$A$6:$A$305,0))="Program",INDEX($C$6:$C$305,MATCH($C10,$A$6:$A$305,0))="Portfolio"),1,0),0),0))) | AA10: =IF(AND($A10<>"",$E10="",OR($Q10=1,$D10="Proposed")),1,0) | AB10: =IF(AND($A10<>"",$B10="Program",$F10="",$Q10=1),1,0) | AC10: =IF(OR($A10="",$D10="Completed",$D10="Terminated"),0,IF($C10="",1,IF($C10="Portfolio",0,IF($C10="Outside the portfolio",IF($Q10=1,2,0),IF($B10="Project",IF(IFERROR(INDEX($B$6:$B$305,MATCH($C10,$A$6:$A$305,0)),"")="Program",0,1),1))))) | AD10: =IF(AND($A10<>"",OR($M10="■ Red",$M10="◧ Amber"),$L10=""),1,0) | AE10: =$AA10+$AB10+IF($AC10>0,1,0)+$AD10+$AG10+$AH10 | AF10: Waterfall | AG10: =IF(AND($A10<>"",$K10<>"",$C10<>"Portfolio",$D10<>"Completed",$D10<>"Terminated"),1,0) | AH10: =IF(AND($A10<>"",COUNTIF($A$6:$A$305,$A10)>1),1,0) | AI10: =IF(AND($A10<>"",$C10="Portfolio"),COUNTIFS($C$6:$C10,"Portfolio",$A$6:$A10,"<>"),"")
A11: Security and Compliance Program | B11: Program | C11: Portfolio | D11: Active | E11: Imani (Security Lead) | F11: Priya (CTO) | G11: Pass the annual audit with no major findings | H11: 46416 | K11: 350000 | M11: =IF($A11="","",IF($D11="","Not read",IF($Q11=0,"Not counted",IF(MAX($X11,$Y11)=3,"■ Red",IF(MAX($X11,$Y11)=2,"◧ Amber",IF(MAX($X11,$Y11)=1,"□ On track","Not read")))))) | N11: =IF(OR($A11="",$B11<>"Program"),"","■ "&COUNTIFS($C$6:$C$305,$A11,$M$6:$M$305,"■ Red")&" Red, ◧ "&COUNTIFS($C$6:$C$305,$A11,$M$6:$M$305,"◧ Amber")&" Amber") | O11: =IF(OR($A11="",$E11=""),"",COUNTIFS($E$6:$E$305,$E11,$D$6:$D$305,"Active")+COUNTIFS($E$6:$E$305,$E11,$D$6:$D$305,"Paused")) | P11: =IF($A11="","",IF($AE11=0,"○ Clear",IF($AA11=1,"△ No owner",IF($AC11=1,"△ Check Sits under",IF($AC11=2,"△ Outside the portfolio",IF($AB11=1,"△ No sponsor",IF($AH11=1,"△ Name used twice",IF($AG11=1,"△ Budget only counts under Portfolio","△ No variance note"))))))&IF($AE11>1," (+"&($AE11-1)&" more)",""))) | Q11: =IF(AND($A11<>"",OR($D11="Active",$D11="Paused")),1,0) | R11: =IFERROR(INDEX($A$6:$A$305,MATCH(4,$S$6:$S$305,0)),"") | S11: =IF(AND($A11<>"",$B11="Program"),COUNTIFS($B$6:$B11,"Program",$A$6:$A11,"<>"),"") | T11: =IF(AND($A11<>"",$B11="Program"),SUMPRODUCT(MAX(($C$6:$C$305=$A11)*($B$6:$B$305="Project")*($D$6:$D$305<>"Proposed")*$I$6:$I$305)),0) | U11: =IF($I11<>"",$I11,IF($T11>0,$T11,"")) | V11: =IF(AND($A11<>"",$B11="Program"),SUMIFS($J$6:$J$305,$C$6:$C$305,$A11,$B$6:$B$305,"Project",$D$6:$D$305,"<>Proposed"),0) | W11: =IF(AND($A11<>"",$B11="Program"),COUNTIFS($C$6:$C$305,$A11,$B$6:$B$305,"Project",$D$6:$D$305,"<>Proposed")-COUNTIFS($C$6:$C$305,$A11,$B$6:$B$305,"Project",$D$6:$D$305,"<>Proposed",$J$6:$J$305,">=0"),0) | X11: =IF(OR($Q11=0,$H11="",$AF11="Sprint"),0,IF(AND($B11="Project",$H11<TODAY()),3,IF($U11="",0,IF($U11<=$H11,1,IF(NETWORKDAYS($H11,$U11)-1>IF($B11="Program",Checks!$B$7,Checks!$B$6),3,2))))) | Y11: =IF(OR($Q11=0,$K11="",$K11=0,$AF11="Sprint"),0,IF(AND($B11="Project",$J11=""),0,IF(IF($B11="Program",$V11,$J11)>$K11*(1+Checks!$B$8),3,IF(IF($B11="Program",$V11,$J11)>$K11,2,IF(AND($B11="Program",OR($W11>0,$V11=0)),0,1))))) | Z11: =IF($A11="",0,IF($C11="Portfolio",1,IF(AND($B11="Project",$C11<>"",$C11<>"Outside the portfolio"),IFERROR(IF(AND(INDEX($B$6:$B$305,MATCH($C11,$A$6:$A$305,0))="Program",INDEX($C$6:$C$305,MATCH($C11,$A$6:$A$305,0))="Portfolio"),1,0),0),0))) | AA11: =IF(AND($A11<>"",$E11="",OR($Q11=1,$D11="Proposed")),1,0) | AB11: =IF(AND($A11<>"",$B11="Program",$F11="",$Q11=1),1,0) | AC11: =IF(OR($A11="",$D11="Completed",$D11="Terminated"),0,IF($C11="",1,IF($C11="Portfolio",0,IF($C11="Outside the portfolio",IF($Q11=1,2,0),IF($B11="Project",IF(IFERROR(INDEX($B$6:$B$305,MATCH($C11,$A$6:$A$305,0)),"")="Program",0,1),1))))) | AD11: =IF(AND($A11<>"",OR($M11="■ Red",$M11="◧ Amber"),$L11=""),1,0) | AE11: =$AA11+$AB11+IF($AC11>0,1,0)+$AD11+$AG11+$AH11 | AG11: =IF(AND($A11<>"",$K11<>"",$C11<>"Portfolio",$D11<>"Completed",$D11<>"Terminated"),1,0) | AH11: =IF(AND($A11<>"",COUNTIF($A$6:$A$305,$A11)>1),1,0) | AI11: =IF(AND($A11<>"",$C11="Portfolio"),COUNTIFS($C$6:$C11,"Portfolio",$A$6:$A11,"<>"),"")
A12: Penetration Test Remediation | B12: Project | C12: Security and Compliance Program | D12: Active | E12: Imani (Security Lead) | G12: Pass the annual audit with no major findings | H12: 46304 | I12: 46325 | J12: 40000 | L12: Two criticals closed; the third needs a vendor patch. Imani | M12: =IF($A12="","",IF($D12="","Not read",IF($Q12=0,"Not counted",IF(MAX($X12,$Y12)=3,"■ Red",IF(MAX($X12,$Y12)=2,"◧ Amber",IF(MAX($X12,$Y12)=1,"□ On track","Not read")))))) | N12: =IF(OR($A12="",$B12<>"Program"),"","■ "&COUNTIFS($C$6:$C$305,$A12,$M$6:$M$305,"■ Red")&" Red, ◧ "&COUNTIFS($C$6:$C$305,$A12,$M$6:$M$305,"◧ Amber")&" Amber") | O12: =IF(OR($A12="",$E12=""),"",COUNTIFS($E$6:$E$305,$E12,$D$6:$D$305,"Active")+COUNTIFS($E$6:$E$305,$E12,$D$6:$D$305,"Paused")) | P12: =IF($A12="","",IF($AE12=0,"○ Clear",IF($AA12=1,"△ No owner",IF($AC12=1,"△ Check Sits under",IF($AC12=2,"△ Outside the portfolio",IF($AB12=1,"△ No sponsor",IF($AH12=1,"△ Name used twice",IF($AG12=1,"△ Budget only counts under Portfolio","△ No variance note"))))))&IF($AE12>1," (+"&($AE12-1)&" more)",""))) | Q12: =IF(AND($A12<>"",OR($D12="Active",$D12="Paused")),1,0) | R12: =IFERROR(INDEX($A$6:$A$305,MATCH(5,$S$6:$S$305,0)),"") | S12: =IF(AND($A12<>"",$B12="Program"),COUNTIFS($B$6:$B12,"Program",$A$6:$A12,"<>"),"") | T12: =IF(AND($A12<>"",$B12="Program"),SUMPRODUCT(MAX(($C$6:$C$305=$A12)*($B$6:$B$305="Project")*($D$6:$D$305<>"Proposed")*$I$6:$I$305)),0) | U12: =IF($I12<>"",$I12,IF($T12>0,$T12,"")) | V12: =IF(AND($A12<>"",$B12="Program"),SUMIFS($J$6:$J$305,$C$6:$C$305,$A12,$B$6:$B$305,"Project",$D$6:$D$305,"<>Proposed"),0) | W12: =IF(AND($A12<>"",$B12="Program"),COUNTIFS($C$6:$C$305,$A12,$B$6:$B$305,"Project",$D$6:$D$305,"<>Proposed")-COUNTIFS($C$6:$C$305,$A12,$B$6:$B$305,"Project",$D$6:$D$305,"<>Proposed",$J$6:$J$305,">=0"),0) | X12: =IF(OR($Q12=0,$H12="",$AF12="Sprint"),0,IF(AND($B12="Project",$H12<TODAY()),3,IF($U12="",0,IF($U12<=$H12,1,IF(NETWORKDAYS($H12,$U12)-1>IF($B12="Program",Checks!$B$7,Checks!$B$6),3,2))))) | Y12: =IF(OR($Q12=0,$K12="",$K12=0,$AF12="Sprint"),0,IF(AND($B12="Project",$J12=""),0,IF(IF($B12="Program",$V12,$J12)>$K12*(1+Checks!$B$8),3,IF(IF($B12="Program",$V12,$J12)>$K12,2,IF(AND($B12="Program",OR($W12>0,$V12=0)),0,1))))) | Z12: =IF($A12="",0,IF($C12="Portfolio",1,IF(AND($B12="Project",$C12<>"",$C12<>"Outside the portfolio"),IFERROR(IF(AND(INDEX($B$6:$B$305,MATCH($C12,$A$6:$A$305,0))="Program",INDEX($C$6:$C$305,MATCH($C12,$A$6:$A$305,0))="Portfolio"),1,0),0),0))) | AA12: =IF(AND($A12<>"",$E12="",OR($Q12=1,$D12="Proposed")),1,0) | AB12: =IF(AND($A12<>"",$B12="Program",$F12="",$Q12=1),1,0) | AC12: =IF(OR($A12="",$D12="Completed",$D12="Terminated"),0,IF($C12="",1,IF($C12="Portfolio",0,IF($C12="Outside the portfolio",IF($Q12=1,2,0),IF($B12="Project",IF(IFERROR(INDEX($B$6:$B$305,MATCH($C12,$A$6:$A$305,0)),"")="Program",0,1),1))))) | AD12: =IF(AND($A12<>"",OR($M12="■ Red",$M12="◧ Amber"),$L12=""),1,0) | AE12: =$AA12+$AB12+IF($AC12>0,1,0)+$AD12+$AG12+$AH12 | AF12: Waterfall | AG12: =IF(AND($A12<>"",$K12<>"",$C12<>"Portfolio",$D12<>"Completed",$D12<>"Terminated"),1,0) | AH12: =IF(AND($A12<>"",COUNTIF($A$6:$A$305,$A12)>1),1,0) | AI12: =IF(AND($A12<>"",$C12="Portfolio"),COUNTIFS($C$6:$C12,"Portfolio",$A$6:$A12,"<>"),"")
A13: Laptop Encryption Rollout | B13: Project | C13: Security and Compliance Program | D13: Active | E13: Imani (Security Lead) | H13: 46367 | I13: 46372 | J13: 120000 | L13: Last two offices wait on courier delivery. Imani | M13: =IF($A13="","",IF($D13="","Not read",IF($Q13=0,"Not counted",IF(MAX($X13,$Y13)=3,"■ Red",IF(MAX($X13,$Y13)=2,"◧ Amber",IF(MAX($X13,$Y13)=1,"□ On track","Not read")))))) | N13: =IF(OR($A13="",$B13<>"Program"),"","■ "&COUNTIFS($C$6:$C$305,$A13,$M$6:$M$305,"■ Red")&" Red, ◧ "&COUNTIFS($C$6:$C$305,$A13,$M$6:$M$305,"◧ Amber")&" Amber") | O13: =IF(OR($A13="",$E13=""),"",COUNTIFS($E$6:$E$305,$E13,$D$6:$D$305,"Active")+COUNTIFS($E$6:$E$305,$E13,$D$6:$D$305,"Paused")) | P13: =IF($A13="","",IF($AE13=0,"○ Clear",IF($AA13=1,"△ No owner",IF($AC13=1,"△ Check Sits under",IF($AC13=2,"△ Outside the portfolio",IF($AB13=1,"△ No sponsor",IF($AH13=1,"△ Name used twice",IF($AG13=1,"△ Budget only counts under Portfolio","△ No variance note"))))))&IF($AE13>1," (+"&($AE13-1)&" more)",""))) | Q13: =IF(AND($A13<>"",OR($D13="Active",$D13="Paused")),1,0) | R13: =IFERROR(INDEX($A$6:$A$305,MATCH(6,$S$6:$S$305,0)),"") | S13: =IF(AND($A13<>"",$B13="Program"),COUNTIFS($B$6:$B13,"Program",$A$6:$A13,"<>"),"") | T13: =IF(AND($A13<>"",$B13="Program"),SUMPRODUCT(MAX(($C$6:$C$305=$A13)*($B$6:$B$305="Project")*($D$6:$D$305<>"Proposed")*$I$6:$I$305)),0) | U13: =IF($I13<>"",$I13,IF($T13>0,$T13,"")) | V13: =IF(AND($A13<>"",$B13="Program"),SUMIFS($J$6:$J$305,$C$6:$C$305,$A13,$B$6:$B$305,"Project",$D$6:$D$305,"<>Proposed"),0) | W13: =IF(AND($A13<>"",$B13="Program"),COUNTIFS($C$6:$C$305,$A13,$B$6:$B$305,"Project",$D$6:$D$305,"<>Proposed")-COUNTIFS($C$6:$C$305,$A13,$B$6:$B$305,"Project",$D$6:$D$305,"<>Proposed",$J$6:$J$305,">=0"),0) | X13: =IF(OR($Q13=0,$H13="",$AF13="Sprint"),0,IF(AND($B13="Project",$H13<TODAY()),3,IF($U13="",0,IF($U13<=$H13,1,IF(NETWORKDAYS($H13,$U13)-1>IF($B13="Program",Checks!$B$7,Checks!$B$6),3,2))))) | Y13: =IF(OR($Q13=0,$K13="",$K13=0,$AF13="Sprint"),0,IF(AND($B13="Project",$J13=""),0,IF(IF($B13="Program",$V13,$J13)>$K13*(1+Checks!$B$8),3,IF(IF($B13="Program",$V13,$J13)>$K13,2,IF(AND($B13="Program",OR($W13>0,$V13=0)),0,1))))) | Z13: =IF($A13="",0,IF($C13="Portfolio",1,IF(AND($B13="Project",$C13<>"",$C13<>"Outside the portfolio"),IFERROR(IF(AND(INDEX($B$6:$B$305,MATCH($C13,$A$6:$A$305,0))="Program",INDEX($C$6:$C$305,MATCH($C13,$A$6:$A$305,0))="Portfolio"),1,0),0),0))) | AA13: =IF(AND($A13<>"",$E13="",OR($Q13=1,$D13="Proposed")),1,0) | AB13: =IF(AND($A13<>"",$B13="Program",$F13="",$Q13=1),1,0) | AC13: =IF(OR($A13="",$D13="Completed",$D13="Terminated"),0,IF($C13="",1,IF($C13="Portfolio",0,IF($C13="Outside the portfolio",IF($Q13=1,2,0),IF($B13="Project",IF(IFERROR(INDEX($B$6:$B$305,MATCH($C13,$A$6:$A$305,0)),"")="Program",0,1),1))))) | AD13: =IF(AND($A13<>"",OR($M13="■ Red",$M13="◧ Amber"),$L13=""),1,0) | AE13: =$AA13+$AB13+IF($AC13>0,1,0)+$AD13+$AG13+$AH13 | AF13: Waterfall | AG13: =IF(AND($A13<>"",$K13<>"",$C13<>"Portfolio",$D13<>"Completed",$D13<>"Terminated"),1,0) | AH13: =IF(AND($A13<>"",COUNTIF($A$6:$A$305,$A13)>1),1,0) | AI13: =IF(AND($A13<>"",$C13="Portfolio"),COUNTIFS($C$6:$C13,"Portfolio",$A$6:$A13,"<>"),"")
A14: Partner Portal Launch | B14: Project | C14: Portfolio | D14: Active | E14: Mei (Product Manager) | H14: 46507 | I14: 46507 | J14: 85000 | K14: 80000 | L14: Contract testers cost more than planned; still within 10 percent. Mei | M14: =IF($A14="","",IF($D14="","Not read",IF($Q14=0,"Not counted",IF(MAX($X14,$Y14)=3,"■ Red",IF(MAX($X14,$Y14)=2,"◧ Amber",IF(MAX($X14,$Y14)=1,"□ On track","Not read")))))) | N14: =IF(OR($A14="",$B14<>"Program"),"","■ "&COUNTIFS($C$6:$C$305,$A14,$M$6:$M$305,"■ Red")&" Red, ◧ "&COUNTIFS($C$6:$C$305,$A14,$M$6:$M$305,"◧ Amber")&" Amber") | O14: =IF(OR($A14="",$E14=""),"",COUNTIFS($E$6:$E$305,$E14,$D$6:$D$305,"Active")+COUNTIFS($E$6:$E$305,$E14,$D$6:$D$305,"Paused")) | P14: =IF($A14="","",IF($AE14=0,"○ Clear",IF($AA14=1,"△ No owner",IF($AC14=1,"△ Check Sits under",IF($AC14=2,"△ Outside the portfolio",IF($AB14=1,"△ No sponsor",IF($AH14=1,"△ Name used twice",IF($AG14=1,"△ Budget only counts under Portfolio","△ No variance note"))))))&IF($AE14>1," (+"&($AE14-1)&" more)",""))) | Q14: =IF(AND($A14<>"",OR($D14="Active",$D14="Paused")),1,0) | R14: =IFERROR(INDEX($A$6:$A$305,MATCH(7,$S$6:$S$305,0)),"") | S14: =IF(AND($A14<>"",$B14="Program"),COUNTIFS($B$6:$B14,"Program",$A$6:$A14,"<>"),"") | T14: =IF(AND($A14<>"",$B14="Program"),SUMPRODUCT(MAX(($C$6:$C$305=$A14)*($B$6:$B$305="Project")*($D$6:$D$305<>"Proposed")*$I$6:$I$305)),0) | U14: =IF($I14<>"",$I14,IF($T14>0,$T14,"")) | V14: =IF(AND($A14<>"",$B14="Program"),SUMIFS($J$6:$J$305,$C$6:$C$305,$A14,$B$6:$B$305,"Project",$D$6:$D$305,"<>Proposed"),0) | W14: =IF(AND($A14<>"",$B14="Program"),COUNTIFS($C$6:$C$305,$A14,$B$6:$B$305,"Project",$D$6:$D$305,"<>Proposed")-COUNTIFS($C$6:$C$305,$A14,$B$6:$B$305,"Project",$D$6:$D$305,"<>Proposed",$J$6:$J$305,">=0"),0) | X14: =IF(OR($Q14=0,$H14="",$AF14="Sprint"),0,IF(AND($B14="Project",$H14<TODAY()),3,IF($U14="",0,IF($U14<=$H14,1,IF(NETWORKDAYS($H14,$U14)-1>IF($B14="Program",Checks!$B$7,Checks!$B$6),3,2))))) | Y14: =IF(OR($Q14=0,$K14="",$K14=0,$AF14="Sprint"),0,IF(AND($B14="Project",$J14=""),0,IF(IF($B14="Program",$V14,$J14)>$K14*(1+Checks!$B$8),3,IF(IF($B14="Program",$V14,$J14)>$K14,2,IF(AND($B14="Program",OR($W14>0,$V14=0)),0,1))))) | Z14: =IF($A14="",0,IF($C14="Portfolio",1,IF(AND($B14="Project",$C14<>"",$C14<>"Outside the portfolio"),IFERROR(IF(AND(INDEX($B$6:$B$305,MATCH($C14,$A$6:$A$305,0))="Program",INDEX($C$6:$C$305,MATCH($C14,$A$6:$A$305,0))="Portfolio"),1,0),0),0))) | AA14: =IF(AND($A14<>"",$E14="",OR($Q14=1,$D14="Proposed")),1,0) | AB14: =IF(AND($A14<>"",$B14="Program",$F14="",$Q14=1),1,0) | AC14: =IF(OR($A14="",$D14="Completed",$D14="Terminated"),0,IF($C14="",1,IF($C14="Portfolio",0,IF($C14="Outside the portfolio",IF($Q14=1,2,0),IF($B14="Project",IF(IFERROR(INDEX($B$6:$B$305,MATCH($C14,$A$6:$A$305,0)),"")="Program",0,1),1))))) | AD14: =IF(AND($A14<>"",OR($M14="■ Red",$M14="◧ Amber"),$L14=""),1,0) | AE14: =$AA14+$AB14+IF($AC14>0,1,0)+$AD14+$AG14+$AH14 | AF14: Waterfall | AG14: =IF(AND($A14<>"",$K14<>"",$C14<>"Portfolio",$D14<>"Completed",$D14<>"Terminated"),1,0) | AH14: =IF(AND($A14<>"",COUNTIF($A$6:$A$305,$A14)>1),1,0) | AI14: =IF(AND($A14<>"",$C14="Portfolio"),COUNTIFS($C$6:$C14,"Portfolio",$A$6:$A14,"<>"),"")
A15: Support Tooling Replacement | B15: Project | C15: Support Ops Program | D15: Active | E15: Noor (Support Lead) | H15: 46430 | I15: 46430 | J15: 70000 | M15: =IF($A15="","",IF($D15="","Not read",IF($Q15=0,"Not counted",IF(MAX($X15,$Y15)=3,"■ Red",IF(MAX($X15,$Y15)=2,"◧ Amber",IF(MAX($X15,$Y15)=1,"□ On track","Not read")))))) | N15: =IF(OR($A15="",$B15<>"Program"),"","■ "&COUNTIFS($C$6:$C$305,$A15,$M$6:$M$305,"■ Red")&" Red, ◧ "&COUNTIFS($C$6:$C$305,$A15,$M$6:$M$305,"◧ Amber")&" Amber") | O15: =IF(OR($A15="",$E15=""),"",COUNTIFS($E$6:$E$305,$E15,$D$6:$D$305,"Active")+COUNTIFS($E$6:$E$305,$E15,$D$6:$D$305,"Paused")) | P15: =IF($A15="","",IF($AE15=0,"○ Clear",IF($AA15=1,"△ No owner",IF($AC15=1,"△ Check Sits under",IF($AC15=2,"△ Outside the portfolio",IF($AB15=1,"△ No sponsor",IF($AH15=1,"△ Name used twice",IF($AG15=1,"△ Budget only counts under Portfolio","△ No variance note"))))))&IF($AE15>1," (+"&($AE15-1)&" more)",""))) | Q15: =IF(AND($A15<>"",OR($D15="Active",$D15="Paused")),1,0) | R15: =IFERROR(INDEX($A$6:$A$305,MATCH(8,$S$6:$S$305,0)),"") | S15: =IF(AND($A15<>"",$B15="Program"),COUNTIFS($B$6:$B15,"Program",$A$6:$A15,"<>"),"") | T15: =IF(AND($A15<>"",$B15="Program"),SUMPRODUCT(MAX(($C$6:$C$305=$A15)*($B$6:$B$305="Project")*($D$6:$D$305<>"Proposed")*$I$6:$I$305)),0) | U15: =IF($I15<>"",$I15,IF($T15>0,$T15,"")) | V15: =IF(AND($A15<>"",$B15="Program"),SUMIFS($J$6:$J$305,$C$6:$C$305,$A15,$B$6:$B$305,"Project",$D$6:$D$305,"<>Proposed"),0) | W15: =IF(AND($A15<>"",$B15="Program"),COUNTIFS($C$6:$C$305,$A15,$B$6:$B$305,"Project",$D$6:$D$305,"<>Proposed")-COUNTIFS($C$6:$C$305,$A15,$B$6:$B$305,"Project",$D$6:$D$305,"<>Proposed",$J$6:$J$305,">=0"),0) | X15: =IF(OR($Q15=0,$H15="",$AF15="Sprint"),0,IF(AND($B15="Project",$H15<TODAY()),3,IF($U15="",0,IF($U15<=$H15,1,IF(NETWORKDAYS($H15,$U15)-1>IF($B15="Program",Checks!$B$7,Checks!$B$6),3,2))))) | Y15: =IF(OR($Q15=0,$K15="",$K15=0,$AF15="Sprint"),0,IF(AND($B15="Project",$J15=""),0,IF(IF($B15="Program",$V15,$J15)>$K15*(1+Checks!$B$8),3,IF(IF($B15="Program",$V15,$J15)>$K15,2,IF(AND($B15="Program",OR($W15>0,$V15=0)),0,1))))) | Z15: =IF($A15="",0,IF($C15="Portfolio",1,IF(AND($B15="Project",$C15<>"",$C15<>"Outside the portfolio"),IFERROR(IF(AND(INDEX($B$6:$B$305,MATCH($C15,$A$6:$A$305,0))="Program",INDEX($C$6:$C$305,MATCH($C15,$A$6:$A$305,0))="Portfolio"),1,0),0),0))) | AA15: =IF(AND($A15<>"",$E15="",OR($Q15=1,$D15="Proposed")),1,0) | AB15: =IF(AND($A15<>"",$B15="Program",$F15="",$Q15=1),1,0) | AC15: =IF(OR($A15="",$D15="Completed",$D15="Terminated"),0,IF($C15="",1,IF($C15="Portfolio",0,IF($C15="Outside the portfolio",IF($Q15=1,2,0),IF($B15="Project",IF(IFERROR(INDEX($B$6:$B$305,MATCH($C15,$A$6:$A$305,0)),"")="Program",0,1),1))))) | AD15: =IF(AND($A15<>"",OR($M15="■ Red",$M15="◧ Amber"),$L15=""),1,0) | AE15: =$AA15+$AB15+IF($AC15>0,1,0)+$AD15+$AG15+$AH15 | AF15: Sprint | AG15: =IF(AND($A15<>"",$K15<>"",$C15<>"Portfolio",$D15<>"Completed",$D15<>"Terminated"),1,0) | AH15: =IF(AND($A15<>"",COUNTIF($A$6:$A$305,$A15)>1),1,0) | AI15: =IF(AND($A15<>"",$C15="Portfolio"),COUNTIFS($C$6:$C15,"Portfolio",$A$6:$A15,"<>"),"")
A16: Internal Wiki Cleanup | B16: Project | C16: Outside the portfolio | D16: Paused | E16: Noor (Support Lead) | M16: =IF($A16="","",IF($D16="","Not read",IF($Q16=0,"Not counted",IF(MAX($X16,$Y16)=3,"■ Red",IF(MAX($X16,$Y16)=2,"◧ Amber",IF(MAX($X16,$Y16)=1,"□ On track","Not read")))))) | N16: =IF(OR($A16="",$B16<>"Program"),"","■ "&COUNTIFS($C$6:$C$305,$A16,$M$6:$M$305,"■ Red")&" Red, ◧ "&COUNTIFS($C$6:$C$305,$A16,$M$6:$M$305,"◧ Amber")&" Amber") | O16: =IF(OR($A16="",$E16=""),"",COUNTIFS($E$6:$E$305,$E16,$D$6:$D$305,"Active")+COUNTIFS($E$6:$E$305,$E16,$D$6:$D$305,"Paused")) | P16: =IF($A16="","",IF($AE16=0,"○ Clear",IF($AA16=1,"△ No owner",IF($AC16=1,"△ Check Sits under",IF($AC16=2,"△ Outside the portfolio",IF($AB16=1,"△ No sponsor",IF($AH16=1,"△ Name used twice",IF($AG16=1,"△ Budget only counts under Portfolio","△ No variance note"))))))&IF($AE16>1," (+"&($AE16-1)&" more)",""))) | Q16: =IF(AND($A16<>"",OR($D16="Active",$D16="Paused")),1,0) | R16: =IFERROR(INDEX($A$6:$A$305,MATCH(9,$S$6:$S$305,0)),"") | S16: =IF(AND($A16<>"",$B16="Program"),COUNTIFS($B$6:$B16,"Program",$A$6:$A16,"<>"),"") | T16: =IF(AND($A16<>"",$B16="Program"),SUMPRODUCT(MAX(($C$6:$C$305=$A16)*($B$6:$B$305="Project")*($D$6:$D$305<>"Proposed")*$I$6:$I$305)),0) | U16: =IF($I16<>"",$I16,IF($T16>0,$T16,"")) | V16: =IF(AND($A16<>"",$B16="Program"),SUMIFS($J$6:$J$305,$C$6:$C$305,$A16,$B$6:$B$305,"Project",$D$6:$D$305,"<>Proposed"),0) | W16: =IF(AND($A16<>"",$B16="Program"),COUNTIFS($C$6:$C$305,$A16,$B$6:$B$305,"Project",$D$6:$D$305,"<>Proposed")-COUNTIFS($C$6:$C$305,$A16,$B$6:$B$305,"Project",$D$6:$D$305,"<>Proposed",$J$6:$J$305,">=0"),0) | X16: =IF(OR($Q16=0,$H16="",$AF16="Sprint"),0,IF(AND($B16="Project",$H16<TODAY()),3,IF($U16="",0,IF($U16<=$H16,1,IF(NETWORKDAYS($H16,$U16)-1>IF($B16="Program",Checks!$B$7,Checks!$B$6),3,2))))) | Y16: =IF(OR($Q16=0,$K16="",$K16=0,$AF16="Sprint"),0,IF(AND($B16="Project",$J16=""),0,IF(IF($B16="Program",$V16,$J16)>$K16*(1+Checks!$B$8),3,IF(IF($B16="Program",$V16,$J16)>$K16,2,IF(AND($B16="Program",OR($W16>0,$V16=0)),0,1))))) | Z16: =IF($A16="",0,IF($C16="Portfolio",1,IF(AND($B16="Project",$C16<>"",$C16<>"Outside the portfolio"),IFERROR(IF(AND(INDEX($B$6:$B$305,MATCH($C16,$A$6:$A$305,0))="Program",INDEX($C$6:$C$305,MATCH($C16,$A$6:$A$305,0))="Portfolio"),1,0),0),0))) | AA16: =IF(AND($A16<>"",$E16="",OR($Q16=1,$D16="Proposed")),1,0) | AB16: =IF(AND($A16<>"",$B16="Program",$F16="",$Q16=1),1,0) | AC16: =IF(OR($A16="",$D16="Completed",$D16="Terminated"),0,IF($C16="",1,IF($C16="Portfolio",0,IF($C16="Outside the portfolio",IF($Q16=1,2,0),IF($B16="Project",IF(IFERROR(INDEX($B$6:$B$305,MATCH($C16,$A$6:$A$305,0)),"")="Program",0,1),1))))) | AD16: =IF(AND($A16<>"",OR($M16="■ Red",$M16="◧ Amber"),$L16=""),1,0) | AE16: =$AA16+$AB16+IF($AC16>0,1,0)+$AD16+$AG16+$AH16 | AF16: Waterfall | AG16: =IF(AND($A16<>"",$K16<>"",$C16<>"Portfolio",$D16<>"Completed",$D16<>"Terminated"),1,0) | AH16: =IF(AND($A16<>"",COUNTIF($A$6:$A$305,$A16)>1),1,0) | AI16: =IF(AND($A16<>"",$C16="Portfolio"),COUNTIFS($C$6:$C16,"Portfolio",$A$6:$A16,"<>"),"")
M17: =IF($A17="","",IF($D17="","Not read",IF($Q17=0,"Not counted",IF(MAX($X17,$Y17)=3,"■ Red",IF(MAX($X17,$Y17)=2,"◧ Amber",IF(MAX($X17,$Y17)=1,"□ On track","Not read")))))) | N17: =IF(OR($A17="",$B17<>"Program"),"","■ "&COUNTIFS($C$6:$C$305,$A17,$M$6:$M$305,"■ Red")&" Red, ◧ "&COUNTIFS($C$6:$C$305,$A17,$M$6:$M$305,"◧ Amber")&" Amber") | O17: =IF(OR($A17="",$E17=""),"",COUNTIFS($E$6:$E$305,$E17,$D$6:$D$305,"Active")+COUNTIFS($E$6:$E$305,$E17,$D$6:$D$305,"Paused")) | P17: =IF($A17="","",IF($AE17=0,"○ Clear",IF($AA17=1,"△ No owner",IF($AC17=1,"△ Check Sits under",IF($AC17=2,"△ Outside the portfolio",IF($AB17=1,"△ No sponsor",IF($AH17=1,"△ Name used twice",IF($AG17=1,"△ Budget only counts under Portfolio","△ No variance note"))))))&IF($AE17>1," (+"&($AE17-1)&" more)",""))) | Q17: =IF(AND($A17<>"",OR($D17="Active",$D17="Paused")),1,0) | R17: =IFERROR(INDEX($A$6:$A$305,MATCH(10,$S$6:$S$305,0)),"") | S17: =IF(AND($A17<>"",$B17="Program"),COUNTIFS($B$6:$B17,"Program",$A$6:$A17,"<>"),"") | T17: =IF(AND($A17<>"",$B17="Program"),SUMPRODUCT(MAX(($C$6:$C$305=$A17)*($B$6:$B$305="Project")*($D$6:$D$305<>"Proposed")*$I$6:$I$305)),0) | U17: =IF($I17<>"",$I17,IF($T17>0,$T17,"")) | V17: =IF(AND($A17<>"",$B17="Program"),SUMIFS($J$6:$J$305,$C$6:$C$305,$A17,$B$6:$B$305,"Project",$D$6:$D$305,"<>Proposed"),0) | W17: =IF(AND($A17<>"",$B17="Program"),COUNTIFS($C$6:$C$305,$A17,$B$6:$B$305,"Project",$D$6:$D$305,"<>Proposed")-COUNTIFS($C$6:$C$305,$A17,$B$6:$B$305,"Project",$D$6:$D$305,"<>Proposed",$J$6:$J$305,">=0"),0) | X17: =IF(OR($Q17=0,$H17="",$AF17="Sprint"),0,IF(AND($B17="Project",$H17<TODAY()),3,IF($U17="",0,IF($U17<=$H17,1,IF(NETWORKDAYS($H17,$U17)-1>IF($B17="Program",Checks!$B$7,Checks!$B$6),3,2))))) | Y17: =IF(OR($Q17=0,$K17="",$K17=0,$AF17="Sprint"),0,IF(AND($B17="Project",$J17=""),0,IF(IF($B17="Program",$V17,$J17)>$K17*(1+Checks!$B$8),3,IF(IF($B17="Program",$V17,$J17)>$K17,2,IF(AND($B17="Program",OR($W17>0,$V17=0)),0,1))))) | Z17: =IF($A17="",0,IF($C17="Portfolio",1,IF(AND($B17="Project",$C17<>"",$C17<>"Outside the portfolio"),IFERROR(IF(AND(INDEX($B$6:$B$305,MATCH($C17,$A$6:$A$305,0))="Program",INDEX($C$6:$C$305,MATCH($C17,$A$6:$A$305,0))="Portfolio"),1,0),0),0))) | AA17: =IF(AND($A17<>"",$E17="",OR($Q17=1,$D17="Proposed")),1,0) | AB17: =IF(AND($A17<>"",$B17="Program",$F17="",$Q17=1),1,0) | AC17: =IF(OR($A17="",$D17="Completed",$D17="Terminated"),0,IF($C17="",1,IF($C17="Portfolio",0,IF($C17="Outside the portfolio",IF($Q17=1,2,0),IF($B17="Project",IF(IFERROR(INDEX($B$6:$B$305,MATCH($C17,$A$6:$A$305,0)),"")="Program",0,1),1))))) | AD17: =IF(AND($A17<>"",OR($M17="■ Red",$M17="◧ Amber"),$L17=""),1,0) | AE17: =$AA17+$AB17+IF($AC17>0,1,0)+$AD17+$AG17+$AH17 | AG17: =IF(AND($A17<>"",$K17<>"",$C17<>"Portfolio",$D17<>"Completed",$D17<>"Terminated"),1,0) | AH17: =IF(AND($A17<>"",COUNTIF($A$6:$A$305,$A17)>1),1,0) | AI17: =IF(AND($A17<>"",$C17="Portfolio"),COUNTIFS($C$6:$C17,"Portfolio",$A$6:$A17,"<>"),"")
M18: =IF($A18="","",IF($D18="","Not read",IF($Q18=0,"Not counted",IF(MAX($X18,$Y18)=3,"■ Red",IF(MAX($X18,$Y18)=2,"◧ Amber",IF(MAX($X18,$Y18)=1,"□ On track","Not read")))))) | N18: =IF(OR($A18="",$B18<>"Program"),"","■ "&COUNTIFS($C$6:$C$305,$A18,$M$6:$M$305,"■ Red")&" Red, ◧ "&COUNTIFS($C$6:$C$305,$A18,$M$6:$M$305,"◧ Amber")&" Amber") | O18: =IF(OR($A18="",$E18=""),"",COUNTIFS($E$6:$E$305,$E18,$D$6:$D$305,"Active")+COUNTIFS($E$6:$E$305,$E18,$D$6:$D$305,"Paused")) | P18: =IF($A18="","",IF($AE18=0,"○ Clear",IF($AA18=1,"△ No owner",IF($AC18=1,"△ Check Sits under",IF($AC18=2,"△ Outside the portfolio",IF($AB18=1,"△ No sponsor",IF($AH18=1,"△ Name used twice",IF($AG18=1,"△ Budget only counts under Portfolio","△ No variance note"))))))&IF($AE18>1," (+"&($AE18-1)&" more)",""))) | Q18: =IF(AND($A18<>"",OR($D18="Active",$D18="Paused")),1,0) | R18: =IFERROR(INDEX($A$6:$A$305,MATCH(11,$S$6:$S$305,0)),"") | S18: =IF(AND($A18<>"",$B18="Program"),COUNTIFS($B$6:$B18,"Program",$A$6:$A18,"<>"),"") | T18: =IF(AND($A18<>"",$B18="Program"),SUMPRODUCT(MAX(($C$6:$C$305=$A18)*($B$6:$B$305="Project")*($D$6:$D$305<>"Proposed")*$I$6:$I$305)),0) | U18: =IF($I18<>"",$I18,IF($T18>0,$T18,"")) | V18: =IF(AND($A18<>"",$B18="Program"),SUMIFS($J$6:$J$305,$C$6:$C$305,$A18,$B$6:$B$305,"Project",$D$6:$D$305,"<>Proposed"),0) | W18: =IF(AND($A18<>"",$B18="Program"),COUNTIFS($C$6:$C$305,$A18,$B$6:$B$305,"Project",$D$6:$D$305,"<>Proposed")-COUNTIFS($C$6:$C$305,$A18,$B$6:$B$305,"Project",$D$6:$D$305,"<>Proposed",$J$6:$J$305,">=0"),0) | X18: =IF(OR($Q18=0,$H18="",$AF18="Sprint"),0,IF(AND($B18="Project",$H18<TODAY()),3,IF($U18="",0,IF($U18<=$H18,1,IF(NETWORKDAYS($H18,$U18)-1>IF($B18="Program",Checks!$B$7,Checks!$B$6),3,2))))) | Y18: =IF(OR($Q18=0,$K18="",$K18=0,$AF18="Sprint"),0,IF(AND($B18="Project",$J18=""),0,IF(IF($B18="Program",$V18,$J18)>$K18*(1+Checks!$B$8),3,IF(IF($B18="Program",$V18,$J18)>$K18,2,IF(AND($B18="Program",OR($W18>0,$V18=0)),0,1))))) | Z18: =IF($A18="",0,IF($C18="Portfolio",1,IF(AND($B18="Project",$C18<>"",$C18<>"Outside the portfolio"),IFERROR(IF(AND(INDEX($B$6:$B$305,MATCH($C18,$A$6:$A$305,0))="Program",INDEX($C$6:$C$305,MATCH($C18,$A$6:$A$305,0))="Portfolio"),1,0),0),0))) | AA18: =IF(AND($A18<>"",$E18="",OR($Q18=1,$D18="Proposed")),1,0) | AB18: =IF(AND($A18<>"",$B18="Program",$F18="",$Q18=1),1,0) | AC18: =IF(OR($A18="",$D18="Completed",$D18="Terminated"),0,IF($C18="",1,IF($C18="Portfolio",0,IF($C18="Outside the portfolio",IF($Q18=1,2,0),IF($B18="Project",IF(IFERROR(INDEX($B$6:$B$305,MATCH($C18,$A$6:$A$305,0)),"")="Program",0,1),1))))) | AD18: =IF(AND($A18<>"",OR($M18="■ Red",$M18="◧ Amber"),$L18=""),1,0) | AE18: =$AA18+$AB18+IF($AC18>0,1,0)+$AD18+$AG18+$AH18 | AG18: =IF(AND($A18<>"",$K18<>"",$C18<>"Portfolio",$D18<>"Completed",$D18<>"Terminated"),1,0) | AH18: =IF(AND($A18<>"",COUNTIF($A$6:$A$305,$A18)>1),1,0) | AI18: =IF(AND($A18<>"",$C18="Portfolio"),COUNTIFS($C$6:$C18,"Portfolio",$A$6:$A18,"<>"),"")
M19: =IF($A19="","",IF($D19="","Not read",IF($Q19=0,"Not counted",IF(MAX($X19,$Y19)=3,"■ Red",IF(MAX($X19,$Y19)=2,"◧ Amber",IF(MAX($X19,$Y19)=1,"□ On track","Not read")))))) | N19: =IF(OR($A19="",$B19<>"Program"),"","■ "&COUNTIFS($C$6:$C$305,$A19,$M$6:$M$305,"■ Red")&" Red, ◧ "&COUNTIFS($C$6:$C$305,$A19,$M$6:$M$305,"◧ Amber")&" Amber") | O19: =IF(OR($A19="",$E19=""),"",COUNTIFS($E$6:$E$305,$E19,$D$6:$D$305,"Active")+COUNTIFS($E$6:$E$305,$E19,$D$6:$D$305,"Paused")) | P19: =IF($A19="","",IF($AE19=0,"○ Clear",IF($AA19=1,"△ No owner",IF($AC19=1,"△ Check Sits under",IF($AC19=2,"△ Outside the portfolio",IF($AB19=1,"△ No sponsor",IF($AH19=1,"△ Name used twice",IF($AG19=1,"△ Budget only counts under Portfolio","△ No variance note"))))))&IF($AE19>1," (+"&($AE19-1)&" more)",""))) | Q19: =IF(AND($A19<>"",OR($D19="Active",$D19="Paused")),1,0) | R19: =IFERROR(INDEX($A$6:$A$305,MATCH(12,$S$6:$S$305,0)),"") | S19: =IF(AND($A19<>"",$B19="Program"),COUNTIFS($B$6:$B19,"Program",$A$6:$A19,"<>"),"") | T19: =IF(AND($A19<>"",$B19="Program"),SUMPRODUCT(MAX(($C$6:$C$305=$A19)*($B$6:$B$305="Project")*($D$6:$D$305<>"Proposed")*$I$6:$I$305)),0) | U19: =IF($I19<>"",$I19,IF($T19>0,$T19,"")) | V19: =IF(AND($A19<>"",$B19="Program"),SUMIFS($J$6:$J$305,$C$6:$C$305,$A19,$B$6:$B$305,"Project",$D$6:$D$305,"<>Proposed"),0) | W19: =IF(AND($A19<>"",$B19="Program"),COUNTIFS($C$6:$C$305,$A19,$B$6:$B$305,"Project",$D$6:$D$305,"<>Proposed")-COUNTIFS($C$6:$C$305,$A19,$B$6:$B$305,"Project",$D$6:$D$305,"<>Proposed",$J$6:$J$305,">=0"),0) | X19: =IF(OR($Q19=0,$H19="",$AF19="Sprint"),0,IF(AND($B19="Project",$H19<TODAY()),3,IF($U19="",0,IF($U19<=$H19,1,IF(NETWORKDAYS($H19,$U19)-1>IF($B19="Program",Checks!$B$7,Checks!$B$6),3,2))))) | Y19: =IF(OR($Q19=0,$K19="",$K19=0,$AF19="Sprint"),0,IF(AND($B19="Project",$J19=""),0,IF(IF($B19="Program",$V19,$J19)>$K19*(1+Checks!$B$8),3,IF(IF($B19="Program",$V19,$J19)>$K19,2,IF(AND($B19="Program",OR($W19>0,$V19=0)),0,1))))) | Z19: =IF($A19="",0,IF($C19="Portfolio",1,IF(AND($B19="Project",$C19<>"",$C19<>"Outside the portfolio"),IFERROR(IF(AND(INDEX($B$6:$B$305,MATCH($C19,$A$6:$A$305,0))="Program",INDEX($C$6:$C$305,MATCH($C19,$A$6:$A$305,0))="Portfolio"),1,0),0),0))) | AA19: =IF(AND($A19<>"",$E19="",OR($Q19=1,$D19="Proposed")),1,0) | AB19: =IF(AND($A19<>"",$B19="Program",$F19="",$Q19=1),1,0) | AC19: =IF(OR($A19="",$D19="Completed",$D19="Terminated"),0,IF($C19="",1,IF($C19="Portfolio",0,IF($C19="Outside the portfolio",IF($Q19=1,2,0),IF($B19="Project",IF(IFERROR(INDEX($B$6:$B$305,MATCH($C19,$A$6:$A$305,0)),"")="Program",0,1),1))))) | AD19: =IF(AND($A19<>"",OR($M19="■ Red",$M19="◧ Amber"),$L19=""),1,0) | AE19: =$AA19+$AB19+IF($AC19>0,1,0)+$AD19+$AG19+$AH19 | AG19: =IF(AND($A19<>"",$K19<>"",$C19<>"Portfolio",$D19<>"Completed",$D19<>"Terminated"),1,0) | AH19: =IF(AND($A19<>"",COUNTIF($A$6:$A$305,$A19)>1),1,0) | AI19: =IF(AND($A19<>"",$C19="Portfolio"),COUNTIFS($C$6:$C19,"Portfolio",$A$6:$A19,"<>"),"")
M20: =IF($A20="","",IF($D20="","Not read",IF($Q20=0,"Not counted",IF(MAX($X20,$Y20)=3,"■ Red",IF(MAX($X20,$Y20)=2,"◧ Amber",IF(MAX($X20,$Y20)=1,"□ On track","Not read")))))) | N20: =IF(OR($A20="",$B20<>"Program"),"","■ "&COUNTIFS($C$6:$C$305,$A20,$M$6:$M$305,"■ Red")&" Red, ◧ "&COUNTIFS($C$6:$C$305,$A20,$M$6:$M$305,"◧ Amber")&" Amber") | O20: =IF(OR($A20="",$E20=""),"",COUNTIFS($E$6:$E$305,$E20,$D$6:$D$305,"Active")+COUNTIFS($E$6:$E$305,$E20,$D$6:$D$305,"Paused")) | P20: =IF($A20="","",IF($AE20=0,"○ Clear",IF($AA20=1,"△ No owner",IF($AC20=1,"△ Check Sits under",IF($AC20=2,"△ Outside the portfolio",IF($AB20=1,"△ No sponsor",IF($AH20=1,"△ Name used twice",IF($AG20=1,"△ Budget only counts under Portfolio","△ No variance note"))))))&IF($AE20>1," (+"&($AE20-1)&" more)",""))) | Q20: =IF(AND($A20<>"",OR($D20="Active",$D20="Paused")),1,0) | R20: =IFERROR(INDEX($A$6:$A$305,MATCH(13,$S$6:$S$305,0)),"") | S20: =IF(AND($A20<>"",$B20="Program"),COUNTIFS($B$6:$B20,"Program",$A$6:$A20,"<>"),"") | T20: =IF(AND($A20<>"",$B20="Program"),SUMPRODUCT(MAX(($C$6:$C$305=$A20)*($B$6:$B$305="Project")*($D$6:$D$305<>"Proposed")*$I$6:$I$305)),0) | U20: =IF($I20<>"",$I20,IF($T20>0,$T20,"")) | V20: =IF(AND($A20<>"",$B20="Program"),SUMIFS($J$6:$J$305,$C$6:$C$305,$A20,$B$6:$B$305,"Project",$D$6:$D$305,"<>Proposed"),0) | W20: =IF(AND($A20<>"",$B20="Program"),COUNTIFS($C$6:$C$305,$A20,$B$6:$B$305,"Project",$D$6:$D$305,"<>Proposed")-COUNTIFS($C$6:$C$305,$A20,$B$6:$B$305,"Project",$D$6:$D$305,"<>Proposed",$J$6:$J$305,">=0"),0) | X20: =IF(OR($Q20=0,$H20="",$AF20="Sprint"),0,IF(AND($B20="Project",$H20<TODAY()),3,IF($U20="",0,IF($U20<=$H20,1,IF(NETWORKDAYS($H20,$U20)-1>IF($B20="Program",Checks!$B$7,Checks!$B$6),3,2))))) | Y20: =IF(OR($Q20=0,$K20="",$K20=0,$AF20="Sprint"),0,IF(AND($B20="Project",$J20=""),0,IF(IF($B20="Program",$V20,$J20)>$K20*(1+Checks!$B$8),3,IF(IF($B20="Program",$V20,$J20)>$K20,2,IF(AND($B20="Program",OR($W20>0,$V20=0)),0,1))))) | Z20: =IF($A20="",0,IF($C20="Portfolio",1,IF(AND($B20="Project",$C20<>"",$C20<>"Outside the portfolio"),IFERROR(IF(AND(INDEX($B$6:$B$305,MATCH($C20,$A$6:$A$305,0))="Program",INDEX($C$6:$C$305,MATCH($C20,$A$6:$A$305,0))="Portfolio"),1,0),0),0))) | AA20: =IF(AND($A20<>"",$E20="",OR($Q20=1,$D20="Proposed")),1,0) | AB20: =IF(AND($A20<>"",$B20="Program",$F20="",$Q20=1),1,0) | AC20: =IF(OR($A20="",$D20="Completed",$D20="Terminated"),0,IF($C20="",1,IF($C20="Portfolio",0,IF($C20="Outside the portfolio",IF($Q20=1,2,0),IF($B20="Project",IF(IFERROR(INDEX($B$6:$B$305,MATCH($C20,$A$6:$A$305,0)),"")="Program",0,1),1))))) | AD20: =IF(AND($A20<>"",OR($M20="■ Red",$M20="◧ Amber"),$L20=""),1,0) | AE20: =$AA20+$AB20+IF($AC20>0,1,0)+$AD20+$AG20+$AH20 | AG20: =IF(AND($A20<>"",$K20<>"",$C20<>"Portfolio",$D20<>"Completed",$D20<>"Terminated"),1,0) | AH20: =IF(AND($A20<>"",COUNTIF($A$6:$A$305,$A20)>1),1,0) | AI20: =IF(AND($A20<>"",$C20="Portfolio"),COUNTIFS($C$6:$C20,"Portfolio",$A$6:$A20,"<>"),"")
M21: =IF($A21="","",IF($D21="","Not read",IF($Q21=0,"Not counted",IF(MAX($X21,$Y21)=3,"■ Red",IF(MAX($X21,$Y21)=2,"◧ Amber",IF(MAX($X21,$Y21)=1,"□ On track","Not read")))))) | N21: =IF(OR($A21="",$B21<>"Program"),"","■ "&COUNTIFS($C$6:$C$305,$A21,$M$6:$M$305,"■ Red")&" Red, ◧ "&COUNTIFS($C$6:$C$305,$A21,$M$6:$M$305,"◧ Amber")&" Amber") | O21: =IF(OR($A21="",$E21=""),"",COUNTIFS($E$6:$E$305,$E21,$D$6:$D$305,"Active")+COUNTIFS($E$6:$E$305,$E21,$D$6:$D$305,"Paused")) | P21: =IF($A21="","",IF($AE21=0,"○ Clear",IF($AA21=1,"△ No owner",IF($AC21=1,"△ Check Sits under",IF($AC21=2,"△ Outside the portfolio",IF($AB21=1,"△ No sponsor",IF($AH21=1,"△ Name used twice",IF($AG21=1,"△ Budget only counts under Portfolio","△ No variance note"))))))&IF($AE21>1," (+"&($AE21-1)&" more)",""))) | Q21: =IF(AND($A21<>"",OR($D21="Active",$D21="Paused")),1,0) | R21: =IFERROR(INDEX($A$6:$A$305,MATCH(14,$S$6:$S$305,0)),"") | S21: =IF(AND($A21<>"",$B21="Program"),COUNTIFS($B$6:$B21,"Program",$A$6:$A21,"<>"),"") | T21: =IF(AND($A21<>"",$B21="Program"),SUMPRODUCT(MAX(($C$6:$C$305=$A21)*($B$6:$B$305="Project")*($D$6:$D$305<>"Proposed")*$I$6:$I$305)),0) | U21: =IF($I21<>"",$I21,IF($T21>0,$T21,"")) | V21: =IF(AND($A21<>"",$B21="Program"),SUMIFS($J$6:$J$305,$C$6:$C$305,$A21,$B$6:$B$305,"Project",$D$6:$D$305,"<>Proposed"),0) | W21: =IF(AND($A21<>"",$B21="Program"),COUNTIFS($C$6:$C$305,$A21,$B$6:$B$305,"Project",$D$6:$D$305,"<>Proposed")-COUNTIFS($C$6:$C$305,$A21,$B$6:$B$305,"Project",$D$6:$D$305,"<>Proposed",$J$6:$J$305,">=0"),0) | X21: =IF(OR($Q21=0,$H21="",$AF21="Sprint"),0,IF(AND($B21="Project",$H21<TODAY()),3,IF($U21="",0,IF($U21<=$H21,1,IF(NETWORKDAYS($H21,$U21)-1>IF($B21="Program",Checks!$B$7,Checks!$B$6),3,2))))) | Y21: =IF(OR($Q21=0,$K21="",$K21=0,$AF21="Sprint"),0,IF(AND($B21="Project",$J21=""),0,IF(IF($B21="Program",$V21,$J21)>$K21*(1+Checks!$B$8),3,IF(IF($B21="Program",$V21,$J21)>$K21,2,IF(AND($B21="Program",OR($W21>0,$V21=0)),0,1))))) | Z21: =IF($A21="",0,IF($C21="Portfolio",1,IF(AND($B21="Project",$C21<>"",$C21<>"Outside the portfolio"),IFERROR(IF(AND(INDEX($B$6:$B$305,MATCH($C21,$A$6:$A$305,0))="Program",INDEX($C$6:$C$305,MATCH($C21,$A$6:$A$305,0))="Portfolio"),1,0),0),0))) | AA21: =IF(AND($A21<>"",$E21="",OR($Q21=1,$D21="Proposed")),1,0) | AB21: =IF(AND($A21<>"",$B21="Program",$F21="",$Q21=1),1,0) | AC21: =IF(OR($A21="",$D21="Completed",$D21="Terminated"),0,IF($C21="",1,IF($C21="Portfolio",0,IF($C21="Outside the portfolio",IF($Q21=1,2,0),IF($B21="Project",IF(IFERROR(INDEX($B$6:$B$305,MATCH($C21,$A$6:$A$305,0)),"")="Program",0,1),1))))) | AD21: =IF(AND($A21<>"",OR($M21="■ Red",$M21="◧ Amber"),$L21=""),1,0) | AE21: =$AA21+$AB21+IF($AC21>0,1,0)+$AD21+$AG21+$AH21 | AG21: =IF(AND($A21<>"",$K21<>"",$C21<>"Portfolio",$D21<>"Completed",$D21<>"Terminated"),1,0) | AH21: =IF(AND($A21<>"",COUNTIF($A$6:$A$305,$A21)>1),1,0) | AI21: =IF(AND($A21<>"",$C21="Portfolio"),COUNTIFS($C$6:$C21,"Portfolio",$A$6:$A21,"<>"),"")
